Workbook

Sheet Premissas
A1: Planilha de Validação dos KPIs – CTI (Contabilidade e Finanças – Entrega 01)
A2: Professor: Mauricio Lopes da Cunha · Integrantes: Bruno Nobrega, Kaio Inglez, Mauricio Suster e Yuri Santana
A3: Abas: Premissas (valores que podem ser alterados) · Dados (contas do cenário 1 e ajustes do balanço) · KPIs (indicadores calculados com fórmulas) · Validacao (compara o Excel com o Python).
A4: Cores: células amarelas podem ser alteradas e toda a planilha recalcula; números em azul vieram do arquivo da CTI ou do Python; preto = fórmula.
A5: "n/a" = indicador não calculável (Ano 12 não tem balanço completo, ou divisão por zero).
A7: Premissa | B7: Valor | C7: Unidade | D7: Observação
A8: Parte variável dos custos | B8: 0.3 | C8: % | D8: O arquivo não separa custo fixo e variável.
A9: Alíquota de IR e CSLL | B9: 0.34 | C9: % | D9: IRPJ 25% + CSLL 9%.
A10: Taxa livre de risco (Rf) | B10: 0.1 | C10: % a.a. | D10: Premissa do grupo.
A11: Beta | B11: 0.8 | D11: Setor de concessões.
A12: Prêmio de risco de mercado | B12: 0.06 | C12: % a.a. | D12: Valor usual de mercado.
A13: Custo do capital próprio (Ke) | B13: =B10+B11*B12 -> 0.148 | C13: % a.a. | D13: Fórmula: Rf + Beta × Prêmio.
A14: Custo da dívida (Kd) | B14: 0.1 | C14: % a.a. | D14: Custo médio da dívida nos dados ≈ 10%.
A15: Custo da dívida depois do IR | B15: =B14*(1-B9) -> 0.066 | C15: % a.a. | D15: Fórmula: Kd × (1 − alíquota).
A16: Ticket médio por cliente | B16: 1200 | C16: R$/ano | D16: Usado para estimar o número de clientes.
A17: Churn (perda de clientes) | B17: 0.15 | C17: % a.a.
A18: Gasto de aquisição de clientes | B18: 0.02 | C18: % da receita líquida
A19: Tolerância da validação | B19: 1e-06 | C19: diferença relativa | D19: Diferença aceita entre Excel e Python.

Sheet Dados
A1: Contas do cenário 1 (valores do arquivo da CTI, em R$) e ajustes do balanço
A2: No arquivo, ativo e receitas são positivos; passivo, patrimônio líquido e despesas são negativos. Célula vazia = conta não existe no ano.
A4: Conta | B4: Ano 1 | C4: Ano 2 | D4: Ano 3 | E4: Ano 4 | F4: Ano 5 | G4: Ano 6 | H4: Ano 7 | I4: Ano 8 | J4: Ano 9 | K4: Ano 10 | L4: Ano 11 | M4: Ano 12
A5: Receita | B5: 6.7227293e+09 | C5: 6.1149371e+09 | D5: 6.2512834e+09 | E5: 6.5065321e+09 | F5: 6.8447112e+09 | G5: 7.270773e+09 | H5: 7.7200959e+09 | I5: 8.2489883e+09 | J5: 8.7564156e+09 | K5: 9.3346359e+09 | L5: 9.9306043e+09 | M5: 1.2222538e+10
A6: Tributos | B6: -4.7146421e+08 | C6: -5.038188e+08 | D6: -5.2970248e+08 | E6: -5.573618e+08 | F6: -5.8924558e+08 | G6: -6.260539e+08 | H6: -6.6691881e+08 | I6: -7.1298777e+08 | J6: -7.5618761e+08 | K6: -8.0557525e+08 | L6: -8.5798102e+08 | M6: -1.0567663e+09
A7: Custos | B7: -1.361165e+09 | C7: -1.3332912e+09 | D7: -1.2329527e+09 | E7: -1.2361634e+09 | F7: -1.1278807e+09 | G7: -1.1402219e+09 | H7: -1.269192e+09 | I7: -1.3426291e+09 | J7: -1.4121463e+09 | K7: -1.2772493e+09 | L7: -1.0519925e+09 | M7: -1.0942965e+09
A8: Depreciação e amortização | B8: -6.0357154e+08 | C8: -7.2826846e+08 | D8: -7.7874102e+08 | E8: -8.1395983e+08 | F8: -8.2935664e+08 | G8: -8.4738747e+08 | H8: -8.7055421e+08 | I8: -8.894801e+08 | J8: -9.0441979e+08 | K8: -9.3266699e+08 | L8: -9.559346e+08 | M8: -1.0601655e+09
A9: Resultado operacional | B9: 4.2865286e+09 | C9: 3.5495586e+09 | D9: 3.7098872e+09 | E9: 3.8990471e+09 | F9: 4.2982283e+09 | G9: 4.6571097e+09 | H9: 4.9134309e+09 | I9: 5.3038914e+09 | J9: 5.6836619e+09 | K9: 6.3191444e+09 | L9: 7.0646962e+09 | M9: 9.0113099e+09
A10: Outros resultados operacionais | B10: 39084401 | C10: 42580035 | D10: 47264402 | E10: 45852292 | F10: 45879927 | G10: 47279580 | H10: 48632678 | I10: 50095382 | J10: 51671287 | K10: 53203406 | L10: 54770299 | M10: 1.4736589e+09
A11: Despesas financeiras | B11: -6.939747e+08 | C11: -6.8883059e+08 | D11: -6.2405407e+08 | E11: -5.940416e+08 | F11: -4.3244404e+08 | G11: -2.3163421e+08 | H11: -1.8414899e+08 | I11: -1.7543145e+08 | J11: -1.884766e+08 | K11: -1.1881847e+08 | L11: -40753915 | M11: -19368852
A12: Resultado líquido | B12: 2.443243e+09 | C12: 2.0008338e+09 | D12: 2.1231455e+09 | E12: 2.3181275e+09 | F12: 2.6426065e+09 | G12: 2.9553692e+09 | H12: 3.153307e+09 | I12: 3.4280366e+09 | J12: 3.7347597e+09 | K12: 4.2382405e+09 | L12: 4.8001157e+09 | M12: 7.0938194e+09
A13: Disponível (caixa) | B13: 1.205265e+09 | C13: 1.0224274e+09 | D13: 1.748421e+09 | E13: 1.1173903e+09 | F13: 3.0738637e+08 | G13: 2.6617501e+08 | H13: 4.2769298e+08 | I13: 1.3699641e+09 | J13: 1.9233331e+09 | K13: 2.3253781e+09 | L13: 3.2458099e+09 | M13: 4.1819493e+08
A14: Estoques | B14: 86620.789 | C14: 86620.789 | D14: 86620.789 | E14: 86620.789 | F14: 86620.789 | G14: 86620.789 | H14: 86620.789 | I14: 86620.789 | J14: 86620.789 | K14: 86620.789 | L14: 86620.789
A15: Ativo circulante | B15: 1.7957209e+09 | C15: 1.5679785e+09 | D15: 2.292584e+09 | E15: 1.6556969e+09 | F15: 8.3937858e+08 | G15: 7.9076852e+08 | H15: 9.4074013e+08 | I15: 1.7793987e+09 | J15: 2.208646e+09 | K15: 2.4616719e+09 | L15: 3.2095904e+09 | M15: 3.8771673e+08
A16: Realizável a longo prazo | B16: 6.3902386e+08 | C16: 9.0666119e+08 | D16: 1.2079363e+09 | E16: 1.3723119e+09 | F16: 1.3659136e+09 | G16: 1.6061169e+09 | H16: 1.9442432e+09 | I16: 2.3163389e+09 | J16: 2.4924004e+09 | K16: 2.4317717e+09 | L16: 2.6021544e+09 | M16: 7.5e-08
A17: Ativo permanente | B17: 8.1963823e+09 | C17: 7.880352e+09 | D17: 7.3122049e+09 | E17: 6.6182742e+09 | F17: 5.8619881e+09 | G17: 5.1272137e+09 | H17: 4.3276495e+09 | I17: 3.4877347e+09 | J17: 2.7591361e+09 | K17: 1.9238259e+09 | L17: 1.0340671e+09 | M17: -2.9776239e+08
A18: Total do ativo | B18: 1.0631127e+10 | C18: 1.0354992e+10 | D18: 1.0812725e+10 | E18: 9.646283e+09 | F18: 8.0672802e+09 | G18: 7.5240991e+09 | H18: 7.2126328e+09 | I18: 7.5834723e+09 | J18: 7.4601825e+09 | K18: 6.8172696e+09 | L18: 6.8458119e+09 | M18: 89954344
A19: Passivo circulante (como vem no arquivo) | B19: -1.0809281e+09 | C19: -1.3577047e+09 | D19: -1.7620307e+09 | E19: -4.9809765e+08 | F19: 1.2632153e+09 | G19: 2.0011966e+09 | H19: 2.4758279e+09 | I19: 2.3278263e+09 | J19: 2.7293588e+09 | K19: 3.8069341e+09 | L19: 4.3167476e+09 | M19: -1.1513975e+08
A20: Empréstimos de curto prazo | B20: -2.7910236e+08 | C20: -3.283839e+08 | D20: -3.6928381e+08 | E20: 8.3879117e+08 | F20: 2.0402141e+09 | G20: 2.8986912e+09 | H20: 3.7577055e+09 | I20: 4.0777106e+09 | J20: 4.4183303e+09 | K20: 4.7818958e+09 | L20: 5.1683609e+09 | M20: -2.76e-07
A21: Empréstimos de longo prazo | B21: -5.6492566e+09 | C21: -5.6492566e+09 | D21: -5.6492566e+09 | E21: -5.6492566e+09 | F21: -5.6492566e+09 | G21: -5.6492566e+09 | H21: -5.6492566e+09 | I21: -5.6446442e+09 | J21: -5.6398899e+09 | K21: -5.6349237e+09 | L21: -5.6296337e+09
A22: Provisão para contingências | B22: -38502465 | C22: -38502465 | D22: -38502465 | E22: -38502465 | F22: -38502465 | G22: -38502465 | H22: -38502465 | I22: -38502465 | J22: -38502465 | K22: -38502465 | L22: -38502465
A23: Outros débitos de longo prazo | B23: -1.8480047e+09 | C23: -1.8480047e+09 | D23: -1.8480047e+09 | E23: -1.8480047e+09 | F23: -1.8480047e+09 | G23: -1.8480047e+09 | H23: -1.8480047e+09 | I23: -1.8480047e+09 | J23: -1.8480047e+09 | K23: -1.8480047e+09 | L23: -1.8480047e+09
A24: Patrimônio líquido | B24: -2.0144352e+09 | C24: -1.4615232e+09 | D24: -1.5149306e+09 | E24: -1.6124216e+09 | F24: -1.7947317e+09 | G24: -1.989532e+09 | H24: -2.1526969e+09 | I24: -2.3801472e+09 | J24: -2.6631442e+09 | K24: -3.1027729e+09 | L24: -3.6464187e+09
A26: Ajustes e valores auxiliares (fórmulas)
A27: Balanço completo? (1 = sim; Ano 12 = 0) | B27: =IF(B24="",0,1) -> 1 | C27: =IF(C24="",0,1) -> 1 | D27: =IF(D24="",0,1) -> 1 | E27: =IF(E24="",0,1) -> 1 | F27: =IF(F24="",0,1) -> 1 | G27: =IF(G24="",0,1) -> 1 | H27: =IF(H24="",0,1) -> 1 | I27: =IF(I24="",0,1) -> 1 | ... M27: =IF(M24="",0,1) -> 0
A28: Dívida bruta = −(empréstimos CP + LP) | B28: =-(B20+B21) -> 5.928359e+09 | C28: =-(C20+C21) -> 5.9776405e+09 | D28: =-(D20+D21) -> 6.0185404e+09 | E28: =-(E20+E21) -> 4.8104655e+09 | F28: =-(F20+F21) -> 3.6090425e+09 | G28: =-(G20+G21) -> 2.7505654e+09 | H28: =-(H20+H21) -> 1.8915511e+09 | I28: =-(I20+I21) -> 1.5669337e+09 | ... M28: =-(M20+M21) -> 2.76e-07
A29: Parte da dívida que vence no ano seguinte | B29: =MAX(0,B28-C28) -> 0 | C29: =MAX(0,C28-D28) -> 0 | D29: =MAX(0,D28-E28) -> 1.208075e+09 | E29: =MAX(0,E28-F28) -> 1.201423e+09 | F29: =MAX(0,F28-G28) -> 8.584771e+08 | G29: =MAX(0,G28-H28) -> 8.5901427e+08 | H29: =MAX(0,H28-I28) -> 3.2461747e+08 | I29: =MAX(0,I28-J28) -> 3.4537409e+08 | ... L29: =MAX(0,L28-M28) -> 4.6127285e+08 | M29: =MAX(0,M28) -> 2.76e-07
A30: Passivo circulante ajustado (PC*) | B30: =-B19+B20+B29 -> 8.018257e+08 | C30: =-C19+C20+C29 -> 1.0293208e+09 | D30: =-D19+D20+D29 -> 2.6008219e+09 | E30: =-E19+E20+E29 -> 2.5383118e+09 | F30: =-F19+F20+F29 -> 1.6354759e+09 | G30: =-G19+G20+G29 -> 1.7565089e+09 | H30: =-H19+H20+H29 -> 1.6064951e+09 | I30: =-I19+I20+I29 -> 2.0952584e+09 | ... M30: =-M19+M20+M29 -> 1.1513975e+08
A31: Exigível a longo prazo ajustado (ELP*) | B31: =B28-B29-B22-B23 -> 7.8148661e+09 | C31: =C28-C29-C22-C23 -> 7.8641477e+09 | D31: =D28-D29-D22-D23 -> 6.6969726e+09 | E31: =E28-E29-E22-E23 -> 5.4955496e+09 | F31: =F28-F29-F22-F23 -> 4.6370726e+09 | G31: =G28-G29-G22-G23 -> 3.7780583e+09 | H31: =H28-H29-H22-H23 -> 3.4534408e+09 | I31: =I28-I29-I22-I23 -> 3.1080667e+09 | ... M31: =M28-M29-M22-M23 -> 0
A32: Exigível total (PC* + ELP*) | B32: =B30+B31 -> 8.6166918e+09 | C32: =C30+C31 -> 8.8934685e+09 | D32: =D30+D31 -> 9.2977945e+09 | E32: =E30+E31 -> 8.0338614e+09 | F32: =F30+F31 -> 6.2725485e+09 | G32: =G30+G31 -> 5.5345671e+09 | H32: =H30+H31 -> 5.0599359e+09 | I32: =I30+I31 -> 5.2033251e+09 | ... M32: =M30+M31 -> 1.1513975e+08
A33: Patrimônio líquido (positivo) | B33: =-B24 -> 2.0144352e+09 | C33: =-C24 -> 1.4615232e+09 | D33: =-D24 -> 1.5149306e+09 | E33: =-E24 -> 1.6124216e+09 | F33: =-F24 -> 1.7947317e+09 | G33: =-G24 -> 1.989532e+09 | H33: =-H24 -> 2.1526969e+09 | I33: =-I24 -> 2.3801472e+09 | ... M33: =-M24 -> 0
A34: Patrimônio líquido no início do ano | B34: =B33 -> 2.0144352e+09 | C34: =B33 -> 2.0144352e+09 | D34: =C33 -> 1.4615232e+09 | E34: =D33 -> 1.5149306e+09 | F34: =E33 -> 1.6124216e+09 | G34: =F33 -> 1.7947317e+09 | H34: =G33 -> 1.989532e+09 | I34: =H33 -> 2.1526969e+09 | J34: =I33 -> 2.3801472e+09 | ... M34: =L33 -> 3.6464187e+09
A35: Dívida bruta no início do ano | B35: =B28 -> 5.928359e+09 | C35: =B28 -> 5.928359e+09 | D35: =C28 -> 5.9776405e+09 | E35: =D28 -> 6.0185404e+09 | F35: =E28 -> 4.8104655e+09 | G35: =F28 -> 3.6090425e+09 | H35: =G28 -> 2.7505654e+09 | I35: =H28 -> 1.8915511e+09 | J35: =I28 -> 1.5669337e+09 | ... M35: =L28 -> 4.6127285e+08
A36: Capital investido (PL + dívida no início do ano) | B36: =B34+B35 -> 7.9427942e+09 | C36: =C34+C35 -> 7.9427942e+09 | D36: =D34+D35 -> 7.4391638e+09 | E36: =E34+E35 -> 7.533471e+09 | F36: =F34+F35 -> 6.422887e+09 | G36: =G34+G35 -> 5.4037742e+09 | H36: =H34+H35 -> 4.7400974e+09 | I36: =I34+I35 -> 4.044248e+09 | ... M36: =M34+M35 -> 4.1076915e+09
A37: EBIT (resultado operacional + outros) | B37: =B9+B10 -> 4.325613e+09 | C37: =C9+C10 -> 3.5921387e+09 | D37: =D9+D10 -> 3.7571516e+09 | E37: =E9+E10 -> 3.9448994e+09 | F37: =F9+F10 -> 4.3441082e+09 | G37: =G9+G10 -> 4.7043893e+09 | H37: =H9+H10 -> 4.9620636e+09 | I37: =I9+I10 -> 5.3539868e+09 | ... M37: =M9+M10 -> 1.0484969e+10
A38: Clientes (receita líquida ÷ ticket) – simulado | B38: =(B5+B6)/Premissas!$B$16 -> 5209387.6 | C38: =(C5+C6)/Premissas!$B$16 -> 4675931.9 | D38: =(D5+D6)/Premissas!$B$16 -> 4767984.1 | E38: =(E5+E6)/Premissas!$B$16 -> 4957641.9 | F38: =(F5+F6)/Premissas!$B$16 -> 5212888 | G38: =(G5+G6)/Premissas!$B$16 -> 5537265.9 | H38: =(H5+H6)/Premissas!$B$16 -> 5877647.6 | I38: =(I5+I6)/Premissas!$B$16 -> 6280000.5 | ... M38: =(M5+M6)/Premissas!$B$16 -> 9304809.9
A39: Novos clientes no ano – simulado | B39: =Premissas!$B$17*B38 -> 781408.14 | C39: =C38-B38+Premissas!$B$17*B38 -> 247952.49 | D39: =D38-C38+Premissas!$B$17*C38 -> 793441.96 | E39: =E38-D38+Premissas!$B$17*D38 -> 904855.39 | F39: =F38-E38+Premissas!$B$17*E38 -> 998892.39 | G39: =G38-F38+Premissas!$B$17*F38 -> 1106311.1 | H39: =H38-G38+Premissas!$B$17*G38 -> 1170971.6 | I39: =I38-H38+Premissas!$B$17*H38 -> 1284000 | J39: =J38-I38+Premissas!$B$17*I38 -> 1328856.3 | ... M39: =M38-L38+Premissas!$B$17*L38 -> 2878368.4
A41: Por que ajustar: a linha de empréstimos de curto prazo fica positiva a partir do Ano 4 (o modelo acumula ali as amortizações). A dívida é a soma das duas linhas e a parte que vence no ano seguinte vai para o passivo circulante.

Sheet KPIs
A1: KPIs do cenário 1 – calculados com fórmulas (IDs iguais aos do dicionário)
A2: * PC e ELP ajustados (ver aba Dados). Valores em R$; margens em %.
A4: ID | B4: Indicador | C4: Ano 1 | D4: Ano 2 | E4: Ano 3 | F4: Ano 4 | G4: Ano 5 | H4: Ano 6 | I4: Ano 7 | J4: Ano 8 | K4: Ano 9 | L4: Ano 10 | M4: Ano 11 | N4: Ano 12 | O4: Unidade
A5: A. Receita, custos e margens
A6: A01 | B6: Receita bruta | C6: =Dados!B5 -> 6.7227293e+09 | D6: =Dados!C5 -> 6.1149371e+09 | E6: =Dados!D5 -> 6.2512834e+09 | F6: =Dados!E5 -> 6.5065321e+09 | G6: =Dados!F5 -> 6.8447112e+09 | H6: =Dados!G5 -> 7.270773e+09 | I6: =Dados!H5 -> 7.7200959e+09 | J6: =Dados!I5 -> 8.2489883e+09 | ... N6: =Dados!M5 -> 1.2222538e+10 | O6: R$
A7: A03 | B7: Receita líquida | C7: =Dados!B5+Dados!B6 -> 6.2512651e+09 | D7: =Dados!C5+Dados!C6 -> 5.6111183e+09 | E7: =Dados!D5+Dados!D6 -> 5.7215809e+09 | F7: =Dados!E5+Dados!E6 -> 5.9491703e+09 | G7: =Dados!F5+Dados!F6 -> 6.2554656e+09 | H7: =Dados!G5+Dados!G6 -> 6.6447191e+09 | I7: =Dados!H5+Dados!H6 -> 7.0531771e+09 | J7: =Dados!I5+Dados!I6 -> 7.5360006e+09 | ... N7: =Dados!M5+Dados!M6 -> 1.1165772e+10 | O7: R$
A8: A04 | B8: Custos operacionais | C8: =-Dados!B7 -> 1.361165e+09 | D8: =-Dados!C7 -> 1.3332912e+09 | E8: =-Dados!D7 -> 1.2329527e+09 | F8: =-Dados!E7 -> 1.2361634e+09 | G8: =-Dados!F7 -> 1.1278807e+09 | H8: =-Dados!G7 -> 1.1402219e+09 | I8: =-Dados!H7 -> 1.269192e+09 | J8: =-Dados!I7 -> 1.3426291e+09 | ... N8: =-Dados!M7 -> 1.0942965e+09 | O8: R$
A9: A05 | B9: Custos variáveis (simulado) | C9: =C8*Premissas!$B$8 -> 4.0834949e+08 | D9: =D8*Premissas!$B$8 -> 3.9998737e+08 | E9: =E8*Premissas!$B$8 -> 3.6988581e+08 | F9: =F8*Premissas!$B$8 -> 3.7084901e+08 | G9: =G8*Premissas!$B$8 -> 3.3836421e+08 | H9: =H8*Premissas!$B$8 -> 3.4206658e+08 | I9: =I8*Premissas!$B$8 -> 3.807576e+08 | J9: =J8*Premissas!$B$8 -> 4.0278873e+08 | ... N9: =N8*Premissas!$B$8 -> 3.2828894e+08 | O9: R$
A10: A07 | B10: Margem de contribuição | C10: =C7-C9 -> 5.8429156e+09 | D10: =D7-D9 -> 5.211131e+09 | E10: =E7-E9 -> 5.3516951e+09 | F10: =F7-F9 -> 5.5783213e+09 | G10: =G7-G9 -> 5.9171014e+09 | H10: =H7-H9 -> 6.3026525e+09 | I10: =I7-I9 -> 6.6724195e+09 | J10: =J7-J9 -> 7.1332118e+09 | ... N10: =N7-N9 -> 1.0837483e+10 | O10: R$
A11: A08 | B11: Índice de margem de contribuição | C11: =IF(C7=0,"n/a",C10/C7) -> 0.9346773 | D11: =IF(D7=0,"n/a",D10/D7) -> 0.92871521 | E11: =IF(E7=0,"n/a",E10/E7) -> 0.93535252 | F11: =IF(F7=0,"n/a",F10/F7) -> 0.93766374 | G11: =IF(G7=0,"n/a",G10/G7) -> 0.94590903 | H11: =IF(H7=0,"n/a",H10/H7) -> 0.94852054 | I11: =IF(I7=0,"n/a",I10/I7) -> 0.94601616 | J11: =IF(J7=0,"n/a",J10/J7) -> 0.94655139 | ... N11: =IF(N7=0,"n/a",N10/N7) -> 0.97059863 | O11: %
A12: A10 | B12: EBITDA | C12: =Dados!B37-Dados!B8 -> 4.9291845e+09 | D12: =Dados!C37-Dados!C8 -> 4.3204071e+09 | E12: =Dados!D37-Dados!D8 -> 4.5358926e+09 | F12: =Dados!E37-Dados!E8 -> 4.7588592e+09 | G12: =Dados!F37-Dados!F8 -> 5.1734648e+09 | H12: =Dados!G37-Dados!G8 -> 5.5517768e+09 | I12: =Dados!H37-Dados!H8 -> 5.8326178e+09 | J12: =Dados!I37-Dados!I8 -> 6.2434669e+09 | ... N12: =Dados!M37-Dados!M8 -> 1.1545134e+10 | O12: R$
A13: A11 | B13: Margem EBITDA | C13: =IF(C7=0,"n/a",C12/C7) -> 0.78850992 | D13: =IF(D7=0,"n/a",D12/D7) -> 0.76997256 | E13: =IF(E7=0,"n/a",E12/E7) -> 0.79276911 | F13: =IF(F7=0,"n/a",F12/F7) -> 0.79991982 | G13: =IF(G7=0,"n/a",G12/G7) -> 0.82703114 | H13: =IF(H7=0,"n/a",H12/H7) -> 0.83551715 | I13: =IF(I7=0,"n/a",I12/I7) -> 0.82694901 | J13: =IF(J7=0,"n/a",J12/J7) -> 0.82848545 | ... N13: =IF(N7=0,"n/a",N12/N7) -> 1.0339755 | O13: %
A14: A13 | B14: Lucro líquido | C14: =Dados!B12 -> 2.443243e+09 | D14: =Dados!C12 -> 2.0008338e+09 | E14: =Dados!D12 -> 2.1231455e+09 | F14: =Dados!E12 -> 2.3181275e+09 | G14: =Dados!F12 -> 2.6426065e+09 | H14: =Dados!G12 -> 2.9553692e+09 | I14: =Dados!H12 -> 3.153307e+09 | J14: =Dados!I12 -> 3.4280366e+09 | ... N14: =Dados!M12 -> 7.0938194e+09 | O14: R$
A15: A14 | B15: Margem líquida | C15: =IF(C7=0,"n/a",C14/C7) -> 0.39083976 | D15: =IF(D7=0,"n/a",D14/D7) -> 0.35658379 | E15: =IF(E7=0,"n/a",E14/E7) -> 0.37107672 | F15: =IF(F7=0,"n/a",F14/F7) -> 0.3896556 | G15: =IF(G7=0,"n/a",G14/G7) -> 0.42244761 | H15: =IF(H7=0,"n/a",H14/H7) -> 0.44476963 | I15: =IF(I7=0,"n/a",I14/I7) -> 0.44707611 | J15: =IF(J7=0,"n/a",J14/J7) -> 0.45488805 | ... N15: =IF(N7=0,"n/a",N14/N7) -> 0.63531832 | O15: %
A16: B. Liquidez
A17: B01 | B17: Liquidez corrente | C17: =IF(Dados!B27=1,Dados!B15/Dados!B30,"n/a") -> 2.2395402 | D17: =IF(Dados!C27=1,Dados!C15/Dados!C30,"n/a") -> 1.5233138 | E17: =IF(Dados!D27=1,Dados!D15/Dados!D30,"n/a") -> 0.8814844 | F17: =IF(Dados!E27=1,Dados!E15/Dados!E30,"n/a") -> 0.65228271 | G17: =IF(Dados!F27=1,Dados!F15/Dados!F30,"n/a") -> 0.513232 | H17: =IF(Dados!G27=1,Dados!G15/Dados!G30,"n/a") -> 0.4501933 | I17: =IF(Dados!H27=1,Dados!H15/Dados!H30,"n/a") -> 0.58558543 | J17: =IF(Dados!I27=1,Dados!I15/Dados!I30,"n/a") -> 0.84925028 | ... N17: =IF(Dados!M27=1,Dados!M15/Dados!M30,"n/a") -> n/a | O17: x
A18: B02 | B18: Liquidez seca | C18: =IF(Dados!B27=1,(Dados!B15-Dados!B14)/Dados!B30,"n/a") -> 2.2394322 | D18: =IF(Dados!C27=1,(Dados!C15-Dados!C14)/Dados!C30,"n/a") -> 1.5232296 | E18: =IF(Dados!D27=1,(Dados!D15-Dados!D14)/Dados!D30,"n/a") -> 0.8814511 | F18: =IF(Dados!E27=1,(Dados!E15-Dados!E14)/Dados!E30,"n/a") -> 0.65224859 | G18: =IF(Dados!F27=1,(Dados!F15-Dados!F14)/Dados!F30,"n/a") -> 0.51317903 | H18: =IF(Dados!G27=1,(Dados!G15-Dados!G14)/Dados!G30,"n/a") -> 0.45014399 | I18: =IF(Dados!H27=1,(Dados!H15-Dados!H14)/Dados!H30,"n/a") -> 0.58553151 | J18: =IF(Dados!I27=1,(Dados!I15-Dados!I14)/Dados!I30,"n/a") -> 0.84920894 | ... N18: =IF(Dados!M27=1,(Dados!M15-Dados!M14)/Dados!M30,"n/a") -> n/a | O18: x
A19: B03 | B19: Liquidez imediata | C19: =IF(Dados!B27=1,Dados!B13/Dados!B30,"n/a") -> 1.5031508 | D19: =IF(Dados!C27=1,Dados!C13/Dados!C30,"n/a") -> 0.99330301 | E19: =IF(Dados!D27=1,Dados!D13/Dados!D30,"n/a") -> 0.67225711 | F19: =IF(Dados!E27=1,Dados!E13/Dados!E30,"n/a") -> 0.44021003 | G19: =IF(Dados!F27=1,Dados!F13/Dados!F30,"n/a") -> 0.18794919 | H19: =IF(Dados!G27=1,Dados!G13/Dados!G30,"n/a") -> 0.15153639 | I19: =IF(Dados!H27=1,Dados!H13/Dados!H30,"n/a") -> 0.26622738 | J19: =IF(Dados!I27=1,Dados!I13/Dados!I30,"n/a") -> 0.65384016 | ... N19: =IF(Dados!M27=1,Dados!M13/Dados!M30,"n/a") -> n/a | O19: x
A20: B04 | B20: Liquidez geral | C20: =IF(Dados!B27=1,(Dados!B15+Dados!B16)/Dados!B32,"n/a") -> 0.28256143 | D20: =IF(Dados!C27=1,(Dados!C15+Dados!C16)/Dados!C32,"n/a") -> 0.27825361 | E20: =IF(Dados!D27=1,(Dados!D15+Dados!D16)/Dados!D32,"n/a") -> 0.37648931 | F20: =IF(Dados!E27=1,(Dados!E15+Dados!E16)/Dados!E32,"n/a") -> 0.37690578 | G20: =IF(Dados!F27=1,(Dados!F15+Dados!F16)/Dados!F32,"n/a") -> 0.35157833 | H20: =IF(Dados!G27=1,(Dados!G15+Dados!G16)/Dados!G32,"n/a") -> 0.4330755 | I20: =IF(Dados!H27=1,(Dados!H15+Dados!H16)/Dados!H32,"n/a") -> 0.57016203 | J20: =IF(Dados!I27=1,(Dados!I15+Dados!I16)/Dados!I32,"n/a") -> 0.78713852 | ... N20: =IF(Dados!M27=1,(Dados!M15+Dados!M16)/Dados!M32,"n/a") -> n/a | O20: x
A21: B05 | B21: Capital circulante líquido | C21: =IF(Dados!B27=1,Dados!B15-Dados!B30,"n/a") -> 9.9389517e+08 | D21: =IF(Dados!C27=1,Dados!C15-Dados!C30,"n/a") -> 5.3865773e+08 | E21: =IF(Dados!D27=1,Dados!D15-Dados!D30,"n/a") -> -3.0823796e+08 | F21: =IF(Dados!E27=1,Dados!E15-Dados!E30,"n/a") -> -8.8261489e+08 | G21: =IF(Dados!F27=1,Dados!F15-Dados!F30,"n/a") -> -7.9609735e+08 | H21: =IF(Dados!G27=1,Dados!G15-Dados!G30,"n/a") -> -9.6574034e+08 | I21: =IF(Dados!H27=1,Dados!H15-Dados!H30,"n/a") -> -6.6575497e+08 | J21: =IF(Dados!I27=1,Dados!I15-Dados!I30,"n/a") -> -3.1585961e+08 | ... N21: =IF(Dados!M27=1,Dados!M15-Dados!M30,"n/a") -> n/a | O21: R$
A22: C. Endividamento
A23: C01 | B23: Dívida bruta | C23: =Dados!B28 -> 5.928359e+09 | D23: =Dados!C28 -> 5.9776405e+09 | E23: =Dados!D28 -> 6.0185404e+09 | F23: =Dados!E28 -> 4.8104655e+09 | G23: =Dados!F28 -> 3.6090425e+09 | H23: =Dados!G28 -> 2.7505654e+09 | I23: =Dados!H28 -> 1.8915511e+09 | J23: =Dados!I28 -> 1.5669337e+09 | ... N23: =Dados!M28 -> 2.76e-07 | O23: R$
A24: C03 | B24: Endividamento geral | C24: =IF(Dados!B27=1,Dados!B32/Dados!B18,"n/a") -> 0.81051536 | D24: =IF(Dados!C27=1,Dados!C32/Dados!C18,"n/a") -> 0.8588581 | E24: =IF(Dados!D27=1,Dados!D32/Dados!D18,"n/a") -> 0.85989373 | F24: =IF(Dados!E27=1,Dados!E32/Dados!E18,"n/a") -> 0.8328453 | G24: =IF(Dados!F27=1,Dados!F32/Dados!F18,"n/a") -> 0.77752952 | H24: =IF(Dados!G27=1,Dados!G32/Dados!G18,"n/a") -> 0.73557871 | I24: =IF(Dados!H27=1,Dados!H32/Dados!H18,"n/a") -> 0.70153799 | J24: =IF(Dados!I27=1,Dados!I32/Dados!I18,"n/a") -> 0.68614019 | ... N24: =IF(Dados!M27=1,Dados!M32/Dados!M18,"n/a") -> n/a | O24: %
A25: C04 | B25: Participação de capitais de terceiros | C25: =IF(AND(Dados!B27=1,Dados!B33>0),Dados!B32/Dados!B33,"n/a") -> 4.2774728 | D25: =IF(AND(Dados!C27=1,Dados!C33>0),Dados!C32/Dados!C33,"n/a") -> 6.0850681 | E25: =IF(AND(Dados!D27=1,Dados!D33>0),Dados!D32/Dados!D33,"n/a") -> 6.1374394 | F25: =IF(AND(Dados!E27=1,Dados!E33>0),Dados!E32/Dados!E33,"n/a") -> 4.982482 | G25: =IF(AND(Dados!F27=1,Dados!F33>0),Dados!F32/Dados!F33,"n/a") -> 3.4949783 | H25: =IF(AND(Dados!G27=1,Dados!G33>0),Dados!G32/Dados!G33,"n/a") -> 2.7818437 | I25: =IF(AND(Dados!H27=1,Dados!H33>0),Dados!H32/Dados!H33,"n/a") -> 2.3505102 | J25: =IF(AND(Dados!I27=1,Dados!I33>0),Dados!I32/Dados!I33,"n/a") -> 2.1861358 | ... N25: =IF(AND(Dados!M27=1,Dados!M33>0),Dados!M32/Dados!M33,"n/a") -> n/a | O25: x
A26: C05 | B26: Composição do endividamento | C26: =IF(Dados!B27=1,Dados!B30/Dados!B32,"n/a") -> 0.093054935 | D26: =IF(Dados!C27=1,Dados!C30/Dados!C32,"n/a") -> 0.11573896 | E26: =IF(Dados!D27=1,Dados!D30/Dados!D32,"n/a") -> 0.27972461 | F26: =IF(Dados!E27=1,Dados!E30/Dados!E32,"n/a") -> 0.31595165 | G26: =IF(Dados!F27=1,Dados!F30/Dados!F32,"n/a") -> 0.26073548 | H26: =IF(Dados!G27=1,Dados!G30/Dados!G32,"n/a") -> 0.31737059 | I26: =IF(Dados!H27=1,Dados!H30/Dados!H32,"n/a") -> 0.31749317 | J26: =IF(Dados!I27=1,Dados!I30/Dados!I32,"n/a") -> 0.40267681 | ... N26: =IF(Dados!M27=1,Dados!M30/Dados!M32,"n/a") -> n/a | O26: %
A27: C06 | B27: Imobilização do PL | C27: =IF(AND(Dados!B27=1,Dados!B33>0),Dados!B17/Dados!B33,"n/a") -> 4.068824 | D27: =IF(AND(Dados!C27=1,Dados!C33>0),Dados!C17/Dados!C33,"n/a") -> 5.391876 | E27: =IF(AND(Dados!D27=1,Dados!D33>0),Dados!D17/Dados!D33,"n/a") -> 4.8267591 | F27: =IF(AND(Dados!E27=1,Dados!E33>0),Dados!E17/Dados!E33,"n/a") -> 4.1045558 | G27: =IF(AND(Dados!F27=1,Dados!F33>0),Dados!F17/Dados!F33,"n/a") -> 3.2662197 | H27: =IF(AND(Dados!G27=1,Dados!G33>0),Dados!G17/Dados!G33,"n/a") -> 2.5770954 | I27: =IF(AND(Dados!H27=1,Dados!H33>0),Dados!H17/Dados!H33,"n/a") -> 2.0103385 | J27: =IF(AND(Dados!I27=1,Dados!I33>0),Dados!I17/Dados!I33,"n/a") -> 1.4653441 | ... N27: =IF(AND(Dados!M27=1,Dados!M33>0),Dados!M17/Dados!M33,"n/a") -> n/a | O27: x
A28: C07 | B28: Imobilização dos recursos não correntes | C28: =IF(Dados!B27=1,Dados!B17/(Dados!B33+Dados!B31),"n/a") -> 0.83387232 | D28: =IF(Dados!C27=1,Dados!C17/(Dados!C33+Dados!C31),"n/a") -> 0.84501716 | E28: =IF(Dados!D27=1,Dados!D17/(Dados!D33+Dados!D31),"n/a") -> 0.89043973 | F28: =IF(Dados!E27=1,Dados!E17/(Dados!E33+Dados!E31),"n/a") -> 0.93110593 | G28: =IF(Dados!F27=1,Dados!F17/(Dados!F33+Dados!F31),"n/a") -> 0.91140648 | H28: =IF(Dados!G27=1,Dados!G17/(Dados!G33+Dados!G31),"n/a") -> 0.88896982 | I28: =IF(Dados!H27=1,Dados!H17/(Dados!H33+Dados!H31),"n/a") -> 0.77194848 | J28: =IF(Dados!I27=1,Dados!I17/(Dados!I33+Dados!I31),"n/a") -> 0.63549539 | ... N28: =IF(Dados!M27=1,Dados!M17/(Dados!M33+Dados!M31),"n/a") -> n/a | O28: %
A29: C08 | B29: Dívida líquida / EBITDA | C29: =IF(C12=0,"n/a",(C23-Dados!B13)/C12) -> 0.95818974 | D29: =IF(D12=0,"n/a",(D23-Dados!C13)/D12) -> 1.146932 | E29: =IF(E12=0,"n/a",(E23-Dados!D13)/E12) -> 0.94140663 | F29: =IF(F12=0,"n/a",(F23-Dados!E13)/F12) -> 0.77604212 | G29: =IF(G12=0,"n/a",(G23-Dados!F13)/G12) -> 0.63819051 | H29: =IF(H12=0,"n/a",(H23-Dados!G13)/H12) -> 0.44749465 | I29: =IF(I12=0,"n/a",(I23-Dados!H13)/I12) -> 0.2509779 | J29: =IF(J12=0,"n/a",(J23-Dados!I13)/J12) -> 0.031548113 | ... N29: =IF(N12=0,"n/a",(N23-Dados!M13)/N12) -> -0.036222613 | O29: x
A30: C09 | B30: Cobertura de juros | C30: =IF(Dados!B11=0,"n/a",Dados!B37/-Dados!B11) -> 6.233099 | D30: =IF(Dados!C11=0,"n/a",Dados!C37/-Dados!C11) -> 5.2148361 | E30: =IF(Dados!D11=0,"n/a",Dados!D37/-Dados!D11) -> 6.0205546 | F30: =IF(Dados!E11=0,"n/a",Dados!E37/-Dados!E11) -> 6.6407796 | G30: =IF(Dados!F11=0,"n/a",Dados!F37/-Dados!F11) -> 10.04548 | H30: =IF(Dados!G11=0,"n/a",Dados!G37/-Dados!G11) -> 20.309562 | I30: =IF(Dados!H11=0,"n/a",Dados!H37/-Dados!H11) -> 26.945918 | J30: =IF(Dados!I11=0,"n/a",Dados!I37/-Dados!I11) -> 30.518968 | ... N30: =IF(Dados!M11=0,"n/a",Dados!M37/-Dados!M11) -> 541.33146 | O30: x
A31: D. Criação de valor
A32: D01 | B32: NOPAT | C32: =Dados!B37*(1-Premissas!$B$9) -> 2.8549046e+09 | D32: =Dados!C37*(1-Premissas!$B$9) -> 2.3708115e+09 | E32: =Dados!D37*(1-Premissas!$B$9) -> 2.4797201e+09 | F32: =Dados!E37*(1-Premissas!$B$9) -> 2.6036336e+09 | G32: =Dados!F37*(1-Premissas!$B$9) -> 2.8671114e+09 | H32: =Dados!G37*(1-Premissas!$B$9) -> 3.1048969e+09 | I32: =Dados!H37*(1-Premissas!$B$9) -> 3.274962e+09 | J32: =Dados!I37*(1-Premissas!$B$9) -> 3.5336313e+09 | ... N32: =Dados!M37*(1-Premissas!$B$9) -> 6.9200794e+09 | O32: R$
A33: D06 | B33: WACC | C33: =IF(Dados!B36=0,"n/a",Dados!B34/Dados!B36*Premissas!$B$13+Dados!B35/Dados!B36*Premissas!$B$15) -> 0.086796672 | D33: =IF(Dados!C36=0,"n/a",Dados!C34/Dados!C36*Premissas!$B$13+Dados!C35/Dados!C36*Premissas!$B$15) -> 0.086796672 | E33: =IF(Dados!D36=0,"n/a",Dados!D34/Dados!D36*Premissas!$B$13+Dados!D35/Dados!D36*Premissas!$B$15) -> 0.082109997 | F33: =IF(Dados!E36=0,"n/a",Dados!E34/Dados!E36*Premissas!$B$13+Dados!E35/Dados!E36*Premissas!$B$15) -> 0.082489651 | G33: =IF(Dados!F36=0,"n/a",Dados!F34/Dados!F36*Premissas!$B$13+Dados!F35/Dados!F36*Premissas!$B$15) -> 0.086585535 | H33: =IF(Dados!G36=0,"n/a",Dados!G34/Dados!G36*Premissas!$B$13+Dados!G35/Dados!G36*Premissas!$B$15) -> 0.093234299 | I33: =IF(Dados!H36=0,"n/a",Dados!H34/Dados!H36*Premissas!$B$13+Dados!H35/Dados!H36*Premissas!$B$15) -> 0.10041736 | J33: =IF(Dados!I36=0,"n/a",Dados!I34/Dados!I36*Premissas!$B$13+Dados!I35/Dados!I36*Premissas!$B$15) -> 0.10964746 | ... N33: =IF(Dados!M36=0,"n/a",Dados!M34/Dados!M36*Premissas!$B$13+Dados!M35/Dados!M36*Premissas!$B$15) -> 0.13879182 | O33: %
A34: D08 | B34: EVA | C34: =IF(C33="n/a","n/a",C32-C33*Dados!B36) -> 2.1654965e+09 | D34: =IF(D33="n/a","n/a",D32-D33*Dados!C36) -> 1.6814034e+09 | E34: =IF(E33="n/a","n/a",E32-E33*Dados!D36) -> 1.8688904e+09 | F34: =IF(F33="n/a","n/a",F32-F33*Dados!E36) -> 1.9822002e+09 | G34: =IF(G33="n/a","n/a",G32-G33*Dados!F36) -> 2.3109823e+09 | H34: =IF(H33="n/a","n/a",H32-H33*Dados!G36) -> 2.6010798e+09 | I34: =IF(I33="n/a","n/a",I32-I33*Dados!H36) -> 2.7989739e+09 | J34: =IF(J33="n/a","n/a",J32-J33*Dados!I36) -> 3.0901897e+09 | ... N34: =IF(N33="n/a","n/a",N32-N33*Dados!M36) -> 6.3499654e+09 | O34: R$
A35: D09 | B35: MVA (simulado) | C35: =IF(C33="n/a","n/a",NPV(C33,D34:N34)) -> 1.9306503e+10 | D35: =IF(D33="n/a","n/a",NPV(D33,E34:N34)) -> 1.9300839e+10 | E35: =IF(E33="n/a","n/a",NPV(E33,F34:N34)) -> 1.9549792e+10 | F35: =IF(F33="n/a","n/a",NPV(F33,G34:N34)) -> 1.9140847e+10 | G35: =IF(G33="n/a","n/a",NPV(G33,H34:N34)) -> 1.8117621e+10 | H35: =IF(H33="n/a","n/a",NPV(H33,I34:N34)) -> 1.6704639e+10 | I35: =IF(I33="n/a","n/a",NPV(I33,J34:N34)) -> 1.5146134e+10 | J35: =IF(J33="n/a","n/a",NPV(J33,K34:N34)) -> 1.3280676e+10 | K35: =IF(K33="n/a","n/a",NPV(K33,L34:N34)) -> 1.128239e+10 | L35: =IF(L33="n/a","n/a",NPV(L33,M34:N34)) -> 8.7699433e+09 | M35: =IF(M33="n/a","n/a",NPV(M33,N34:N34)) -> 5.6178597e+09 | N35: =0 -> 0 | O35: R$
A36: E. Clientes (simulado)
A37: E04 | B37: CAC | C37: =IF(Dados!B39<=0,"n/a",C7*Premissas!$B$18/Dados!B39) -> 160 | D37: =IF(Dados!C39<=0,"n/a",D7*Premissas!$B$18/Dados!C39) -> 452.59625 | E37: =IF(Dados!D39<=0,"n/a",E7*Premissas!$B$18/Dados!D39) -> 144.22179 | F37: =IF(Dados!E39<=0,"n/a",F7*Premissas!$B$18/Dados!E39) -> 131.49439 | G37: =IF(Dados!F39<=0,"n/a",G7*Premissas!$B$18/Dados!F39) -> 125.24804 | H37: =IF(Dados!G39<=0,"n/a",H7*Premissas!$B$18/Dados!G39) -> 120.12388 | I37: =IF(Dados!H39<=0,"n/a",I7*Premissas!$B$18/Dados!H39) -> 120.46709 | J37: =IF(Dados!I39<=0,"n/a",J7*Premissas!$B$18/Dados!I39) -> 117.38319 | ... N37: =IF(Dados!M39<=0,"n/a",N7*Premissas!$B$18/Dados!M39) -> 77.584035 | O37: R$/cliente
A38: E06 | B38: LTV | C38: =IF(Dados!B38=0,"n/a",C10/Dados!B38/Premissas!$B$17) -> 7477.4184 | D38: =IF(Dados!C38=0,"n/a",D10/Dados!C38/Premissas!$B$17) -> 7429.7217 | E38: =IF(Dados!D38=0,"n/a",E10/Dados!D38/Premissas!$B$17) -> 7482.8201 | F38: =IF(Dados!E38=0,"n/a",F10/Dados!E38/Premissas!$B$17) -> 7501.3099 | G38: =IF(Dados!F38=0,"n/a",G10/Dados!F38/Premissas!$B$17) -> 7567.2722 | H38: =IF(Dados!G38=0,"n/a",H10/Dados!G38/Premissas!$B$17) -> 7588.1643 | I38: =IF(Dados!H38=0,"n/a",I10/Dados!H38/Premissas!$B$17) -> 7568.1293 | J38: =IF(Dados!I38=0,"n/a",J10/Dados!I38/Premissas!$B$17) -> 7572.4111 | ... N38: =IF(Dados!M38=0,"n/a",N10/Dados!M38/Premissas!$B$17) -> 7764.7891 | O38: R$/cliente
A39: E07 | B39: LTV / CAC | C39: =IF(OR(C37="n/a",C38="n/a"),"n/a",C38/C37) -> 46.733865 | D39: =IF(OR(D37="n/a",D38="n/a"),"n/a",D38/D37) -> 16.415783 | E39: =IF(OR(E37="n/a",E38="n/a"),"n/a",E38/E37) -> 51.884117 | F39: =IF(OR(F37="n/a",F38="n/a"),"n/a",F38/F37) -> 57.046617 | G39: =IF(OR(G37="n/a",G38="n/a"),"n/a",G38/G37) -> 60.41829 | H39: =IF(OR(H37="n/a",H38="n/a"),"n/a",H38/H37) -> 63.169492 | I39: =IF(OR(I37="n/a",I38="n/a"),"n/a",I38/I37) -> 62.823208 | J39: =IF(OR(J37="n/a",J38="n/a"),"n/a",J38/J37) -> 64.510186 | ... N39: =IF(OR(N37="n/a",N38="n/a"),"n/a",N38/N37) -> 100.0823 | O39: x
A41: D09 | B41: MVA na data inicial (valor presente dos EVAs dos Anos 1 a 12) | C41: =NPV(C33,C34:N34) -> 1.9757145e+10 | O41: R$

Sheet Validacao
A1: Validação: Excel (aba KPIs) × Python (script calculo_kpis.py)
A2: Para cada KPI e ano, o valor calculado pelas fórmulas do Excel é comparado com o valor calculado em Python.
B3: Comparações | D3: =COUNTA(G9:G369) -> 361
B4: OK | D4: =COUNTIF(G9:G369,"OK") -> 361
B5: Diferentes | D5: =COUNTIF(G9:G369,"Diferente") -> 0
B6: Resultado | D6: =IF(D5=0,"Todos os KPIs conferem","Verificar diferenças") -> Todos os KPIs conferem
A8: ID | B8: Indicador | C8: Ano | D8: Python | E8: Excel | F8: Diferença | G8: Status
A9: A01 | B9: Receita bruta | C9: 1 | D9: 6.7227293e+09 | E9: =KPIs!C6 -> 6.7227293e+09 | F9: =IF(OR(D9="n/a",E9="n/a"),"",E9-D9) -> 0 | G9: =IF(AND(D9="n/a",E9="n/a"),"OK",IF(OR(D9="n/a",E9="n/a"),"Diferente",IF(ABS(E9-D9)<=Premissas!$B$19*MAX(1,ABS(D9)),"OK","Diferente"))) -> OK
A10: A01 | B10: Receita bruta | C10: 2 | D10: 6.1149371e+09 | E10: =KPIs!D6 -> 6.1149371e+09 | F10: =IF(OR(D10="n/a",E10="n/a"),"",E10-D10) -> 0 | G10: =IF(AND(D10="n/a",E10="n/a"),"OK",IF(OR(D10="n/a",E10="n/a"),"Diferente",IF(ABS(E10-D10)<=Premissas!$B$19*MAX(1,ABS(D10)),"OK","Diferente"))) -> OK
A11: A01 | B11: Receita bruta | C11: 3 | D11: 6.2512834e+09 | E11: =KPIs!E6 -> 6.2512834e+09 | F11: =IF(OR(D11="n/a",E11="n/a"),"",E11-D11) -> 0 | G11: =IF(AND(D11="n/a",E11="n/a"),"OK",IF(OR(D11="n/a",E11="n/a"),"Diferente",IF(ABS(E11-D11)<=Premissas!$B$19*MAX(1,ABS(D11)),"OK","Diferente"))) -> OK
A12: A01 | B12: Receita bruta | C12: 4 | D12: 6.5065321e+09 | E12: =KPIs!F6 -> 6.5065321e+09 | F12: =IF(OR(D12="n/a",E12="n/a"),"",E12-D12) -> 0 | G12: =IF(AND(D12="n/a",E12="n/a"),"OK",IF(OR(D12="n/a",E12="n/a"),"Diferente",IF(ABS(E12-D12)<=Premissas!$B$19*MAX(1,ABS(D12)),"OK","Diferente"))) -> OK
A13: A01 | B13: Receita bruta | C13: 5 | D13: 6.8447112e+09 | E13: =KPIs!G6 -> 6.8447112e+09 | F13: =IF(OR(D13="n/a",E13="n/a"),"",E13-D13) -> 0 | G13: =IF(AND(D13="n/a",E13="n/a"),"OK",IF(OR(D13="n/a",E13="n/a"),"Diferente",IF(ABS(E13-D13)<=Premissas!$B$19*MAX(1,ABS(D13)),"OK","Diferente"))) -> OK
A14: A01 | B14: Receita bruta | C14: 6 | D14: 7.270773e+09 | E14: =KPIs!H6 -> 7.270773e+09 | F14: =IF(OR(D14="n/a",E14="n/a"),"",E14-D14) -> 0 | G14: =IF(AND(D14="n/a",E14="n/a"),"OK",IF(OR(D14="n/a",E14="n/a"),"Diferente",IF(ABS(E14-D14)<=Premissas!$B$19*MAX(1,ABS(D14)),"OK","Diferente"))) -> OK
A15: A01 | B15: Receita bruta | C15: 7 | D15: 7.7200959e+09 | E15: =KPIs!I6 -> 7.7200959e+09 | F15: =IF(OR(D15="n/a",E15="n/a"),"",E15-D15) -> 0 | G15: =IF(AND(D15="n/a",E15="n/a"),"OK",IF(OR(D15="n/a",E15="n/a"),"Diferente",IF(ABS(E15-D15)<=Premissas!$B$19*MAX(1,ABS(D15)),"OK","Diferente"))) -> OK
A16: A01 | B16: Receita bruta | C16: 8 | D16: 8.2489883e+09 | E16: =KPIs!J6 -> 8.2489883e+09 | F16: =IF(OR(D16="n/a",E16="n/a"),"",E16-D16) -> 0 | G16: =IF(AND(D16="n/a",E16="n/a"),"OK",IF(OR(D16="n/a",E16="n/a"),"Diferente",IF(ABS(E16-D16)<=Premissas!$B$19*MAX(1,ABS(D16)),"OK","Diferente"))) -> OK
A17: A01 | B17: Receita bruta | C17: 9 | D17: 8.7564156e+09 | E17: =KPIs!K6 -> 8.7564156e+09 | F17: =IF(OR(D17="n/a",E17="n/a"),"",E17-D17) -> 0 | G17: =IF(AND(D17="n/a",E17="n/a"),"OK",IF(OR(D17="n/a",E17="n/a"),"Diferente",IF(ABS(E17-D17)<=Premissas!$B$19*MAX(1,ABS(D17)),"OK","Diferente"))) -> OK
A18: A01 | B18: Receita bruta | C18: 10 | D18: 9.3346359e+09 | E18: =KPIs!L6 -> 9.3346359e+09 | F18: =IF(OR(D18="n/a",E18="n/a"),"",E18-D18) -> 0 | G18: =IF(AND(D18="n/a",E18="n/a"),"OK",IF(OR(D18="n/a",E18="n/a"),"Diferente",IF(ABS(E18-D18)<=Premissas!$B$19*MAX(1,ABS(D18)),"OK","Diferente"))) -> OK
A19: A01 | B19: Receita bruta | C19: 11 | D19: 9.9306043e+09 | E19: =KPIs!M6 -> 9.9306043e+09 | F19: =IF(OR(D19="n/a",E19="n/a"),"",E19-D19) -> 0 | G19: =IF(AND(D19="n/a",E19="n/a"),"OK",IF(OR(D19="n/a",E19="n/a"),"Diferente",IF(ABS(E19-D19)<=Premissas!$B$19*MAX(1,ABS(D19)),"OK","Diferente"))) -> OK
A20: A01 | B20: Receita bruta | C20: 12 | D20: 1.2222538e+10 | E20: =KPIs!N6 -> 1.2222538e+10 | F20: =IF(OR(D20="n/a",E20="n/a"),"",E20-D20) -> 0 | G20: =IF(AND(D20="n/a",E20="n/a"),"OK",IF(OR(D20="n/a",E20="n/a"),"Diferente",IF(ABS(E20-D20)<=Premissas!$B$19*MAX(1,ABS(D20)),"OK","Diferente"))) -> OK
A21: A03 | B21: Receita líquida | C21: 1 | D21: 6.2512651e+09 | E21: =KPIs!C7 -> 6.2512651e+09 | F21: =IF(OR(D21="n/a",E21="n/a"),"",E21-D21) -> 0 | G21: =IF(AND(D21="n/a",E21="n/a"),"OK",IF(OR(D21="n/a",E21="n/a"),"Diferente",IF(ABS(E21-D21)<=Premissas!$B$19*MAX(1,ABS(D21)),"OK","Diferente"))) -> OK
A22: A03 | B22: Receita líquida | C22: 2 | D22: 5.6111183e+09 | E22: =KPIs!D7 -> 5.6111183e+09 | F22: =IF(OR(D22="n/a",E22="n/a"),"",E22-D22) -> 0 | G22: =IF(AND(D22="n/a",E22="n/a"),"OK",IF(OR(D22="n/a",E22="n/a"),"Diferente",IF(ABS(E22-D22)<=Premissas!$B$19*MAX(1,ABS(D22)),"OK","Diferente"))) -> OK
A23: A03 | B23: Receita líquida | C23: 3 | D23: 5.7215809e+09 | E23: =KPIs!E7 -> 5.7215809e+09 | F23: =IF(OR(D23="n/a",E23="n/a"),"",E23-D23) -> 0 | G23: =IF(AND(D23="n/a",E23="n/a"),"OK",IF(OR(D23="n/a",E23="n/a"),"Diferente",IF(ABS(E23-D23)<=Premissas!$B$19*MAX(1,ABS(D23)),"OK","Diferente"))) -> OK
A24: A03 | B24: Receita líquida | C24: 4 | D24: 5.9491703e+09 | E24: =KPIs!F7 -> 5.9491703e+09 | F24: =IF(OR(D24="n/a",E24="n/a"),"",E24-D24) -> 0 | G24: =IF(AND(D24="n/a",E24="n/a"),"OK",IF(OR(D24="n/a",E24="n/a"),"Diferente",IF(ABS(E24-D24)<=Premissas!$B$19*MAX(1,ABS(D24)),"OK","Diferente"))) -> OK
A25: A03 | B25: Receita líquida | C25: 5 | D25: 6.2554656e+09 | E25: =KPIs!G7 -> 6.2554656e+09 | F25: =IF(OR(D25="n/a",E25="n/a"),"",E25-D25) -> 0 | G25: =IF(AND(D25="n/a",E25="n/a"),"OK",IF(OR(D25="n/a",E25="n/a"),"Diferente",IF(ABS(E25-D25)<=Premissas!$B$19*MAX(1,ABS(D25)),"OK","Diferente"))) -> OK
A26: A03 | B26: Receita líquida | C26: 6 | D26: 6.6447191e+09 | E26: =KPIs!H7 -> 6.6447191e+09 | F26: =IF(OR(D26="n/a",E26="n/a"),"",E26-D26) -> 0 | G26: =IF(AND(D26="n/a",E26="n/a"),"OK",IF(OR(D26="n/a",E26="n/a"),"Diferente",IF(ABS(E26-D26)<=Premissas!$B$19*MAX(1,ABS(D26)),"OK","Diferente"))) -> OK
A27: A03 | B27: Receita líquida | C27: 7 | D27: 7.0531771e+09 | E27: =KPIs!I7 -> 7.0531771e+09 | F27: =IF(OR(D27="n/a",E27="n/a"),"",E27-D27) -> 0 | G27: =IF(AND(D27="n/a",E27="n/a"),"OK",IF(OR(D27="n/a",E27="n/a"),"Diferente",IF(ABS(E27-D27)<=Premissas!$B$19*MAX(1,ABS(D27)),"OK","Diferente"))) -> OK
A28: A03 | B28: Receita líquida | C28: 8 | D28: 7.5360006e+09 | E28: =KPIs!J7 -> 7.5360006e+09 | F28: =IF(OR(D28="n/a",E28="n/a"),"",E28-D28) -> 0 | G28: =IF(AND(D28="n/a",E28="n/a"),"OK",IF(OR(D28="n/a",E28="n/a"),"Diferente",IF(ABS(E28-D28)<=Premissas!$B$19*MAX(1,ABS(D28)),"OK","Diferente"))) -> OK
A29: A03 | B29: Receita líquida | C29: 9 | D29: 8.000228e+09 | E29: =KPIs!K7 -> 8.000228e+09 | F29: =IF(OR(D29="n/a",E29="n/a"),"",E29-D29) -> 0 | G29: =IF(AND(D29="n/a",E29="n/a"),"OK",IF(OR(D29="n/a",E29="n/a"),"Diferente",IF(ABS(E29-D29)<=Premissas!$B$19*MAX(1,ABS(D29)),"OK","Diferente"))) -> OK
A30: A03 | B30: Receita líquida | C30: 10 | D30: 8.5290607e+09 | E30: =KPIs!L7 -> 8.5290607e+09 | F30: =IF(OR(D30="n/a",E30="n/a"),"",E30-D30) -> 0 | G30: =IF(AND(D30="n/a",E30="n/a"),"OK",IF(OR(D30="n/a",E30="n/a"),"Diferente",IF(ABS(E30-D30)<=Premissas!$B$19*MAX(1,ABS(D30)),"OK","Diferente"))) -> OK
A31: A03 | B31: Receita líquida | C31: 11 | D31: 9.0726233e+09 | E31: =KPIs!M7 -> 9.0726233e+09 | F31: =IF(OR(D31="n/a",E31="n/a"),"",E31-D31) -> 0 | G31: =IF(AND(D31="n/a",E31="n/a"),"OK",IF(OR(D31="n/a",E31="n/a"),"Diferente",IF(ABS(E31-D31)<=Premissas!$B$19*MAX(1,ABS(D31)),"OK","Diferente"))) -> OK
A32: A03 | B32: Receita líquida | C32: 12 | D32: 1.1165772e+10 | E32: =KPIs!N7 -> 1.1165772e+10 | F32: =IF(OR(D32="n/a",E32="n/a"),"",E32-D32) -> 0 | G32: =IF(AND(D32="n/a",E32="n/a"),"OK",IF(OR(D32="n/a",E32="n/a"),"Diferente",IF(ABS(E32-D32)<=Premissas!$B$19*MAX(1,ABS(D32)),"OK","Diferente"))) -> OK
A33: A04 | B33: Custos operacionais | C33: 1 | D33: 1.361165e+09 | E33: =KPIs!C8 -> 1.361165e+09 | F33: =IF(OR(D33="n/a",E33="n/a"),"",E33-D33) -> 0 | G33: =IF(AND(D33="n/a",E33="n/a"),"OK",IF(OR(D33="n/a",E33="n/a"),"Diferente",IF(ABS(E33-D33)<=Premissas!$B$19*MAX(1,ABS(D33)),"OK","Diferente"))) -> OK
A34: A04 | B34: Custos operacionais | C34: 2 | D34: 1.3332912e+09 | E34: =KPIs!D8 -> 1.3332912e+09 | F34: =IF(OR(D34="n/a",E34="n/a"),"",E34-D34) -> 0 | G34: =IF(AND(D34="n/a",E34="n/a"),"OK",IF(OR(D34="n/a",E34="n/a"),"Diferente",IF(ABS(E34-D34)<=Premissas!$B$19*MAX(1,ABS(D34)),"OK","Diferente"))) -> OK
A35: A04 | B35: Custos operacionais | C35: 3 | D35: 1.2329527e+09 | E35: =KPIs!E8 -> 1.2329527e+09 | F35: =IF(OR(D35="n/a",E35="n/a"),"",E35-D35) -> 0 | G35: =IF(AND(D35="n/a",E35="n/a"),"OK",IF(OR(D35="n/a",E35="n/a"),"Diferente",IF(ABS(E35-D35)<=Premissas!$B$19*MAX(1,ABS(D35)),"OK","Diferente"))) -> OK
A36: A04 | B36: Custos operacionais | C36: 4 | D36: 1.2361634e+09 | E36: =KPIs!F8 -> 1.2361634e+09 | F36: =IF(OR(D36="n/a",E36="n/a"),"",E36-D36) -> 0 | G36: =IF(AND(D36="n/a",E36="n/a"),"OK",IF(OR(D36="n/a",E36="n/a"),"Diferente",IF(ABS(E36-D36)<=Premissas!$B$19*MAX(1,ABS(D36)),"OK","Diferente"))) -> OK
A37: A04 | B37: Custos operacionais | C37: 5 | D37: 1.1278807e+09 | E37: =KPIs!G8 -> 1.1278807e+09 | F37: =IF(OR(D37="n/a",E37="n/a"),"",E37-D37) -> 0 | G37: =IF(AND(D37="n/a",E37="n/a"),"OK",IF(OR(D37="n/a",E37="n/a"),"Diferente",IF(ABS(E37-D37)<=Premissas!$B$19*MAX(1,ABS(D37)),"OK","Diferente"))) -> OK
A38: A04 | B38: Custos operacionais | C38: 6 | D38: 1.1402219e+09 | E38: =KPIs!H8 -> 1.1402219e+09 | F38: =IF(OR(D38="n/a",E38="n/a"),"",E38-D38) -> 0 | G38: =IF(AND(D38="n/a",E38="n/a"),"OK",IF(OR(D38="n/a",E38="n/a"),"Diferente",IF(ABS(E38-D38)<=Premissas!$B$19*MAX(1,ABS(D38)),"OK","Diferente"))) -> OK
A39: A04 | B39: Custos operacionais | C39: 7 | D39: 1.269192e+09 | E39: =KPIs!I8 -> 1.269192e+09 | F39: =IF(OR(D39="n/a",E39="n/a"),"",E39-D39) -> 0 | G39: =IF(AND(D39="n/a",E39="n/a"),"OK",IF(OR(D39="n/a",E39="n/a"),"Diferente",IF(ABS(E39-D39)<=Premissas!$B$19*MAX(1,ABS(D39)),"OK","Diferente"))) -> OK
A40: A04 | B40: Custos operacionais | C40: 8 | D40: 1.3426291e+09 | E40: =KPIs!J8 -> 1.3426291e+09 | F40: =IF(OR(D40="n/a",E40="n/a"),"",E40-D40) -> 0 | G40: =IF(AND(D40="n/a",E40="n/a"),"OK",IF(OR(D40="n/a",E40="n/a"),"Diferente",IF(ABS(E40-D40)<=Premissas!$B$19*MAX(1,ABS(D40)),"OK","Diferente"))) -> OK
A41: A04 | B41: Custos operacionais | C41: 9 | D41: 1.4121463e+09 | E41: =KPIs!K8 -> 1.4121463e+09 | F41: =IF(OR(D41="n/a",E41="n/a"),"",E41-D41) -> 0 | G41: =IF(AND(D41="n/a",E41="n/a"),"OK",IF(OR(D41="n/a",E41="n/a"),"Diferente",IF(ABS(E41-D41)<=Premissas!$B$19*MAX(1,ABS(D41)),"OK","Diferente"))) -> OK
...
